<?xml version="1.0" encoding="UTF-8"?>
<testsuites>
	<testsuite name="TestUtils-20210214161402" tests="3" file=".py" time="0.006" timestamp="2021-02-14T16:14:02" failures="1" errors="0" skipped="0">
		<testcase classname="TestUtils" name="test_fact" time="0.004" timestamp="2021-02-14T16:14:02" file="test_utils.py" line="10"/>
		<testcase classname="TestUtils" name="test_roots" time="0.001" timestamp="2021-02-14T16:14:02" file="test_utils.py" line="15"/>
		<testcase classname="TestUtils" name="test_integrate" time="0.001" timestamp="2021-02-14T16:14:02" file="test_utils.py" line="21">
			<failure type="AssertionError" message="36.0 != 3"><![CDATA[Traceback (most recent call last):
  File "C:\Users\Denis\OneDrive\Documents\2020-2021_ecam\Q2\2bepi-projet-informatique\Laboratoires\labo1-circleci\test_utils.py", line 22, in test_integrate
    self.assertEqual(utils.integral("2 * x**2 - 4 * x + 2", -2, 4), 3) # 3
AssertionError: 36.0 != 3
]]></failure>
		</testcase>
	</testsuite>
</testsuites>
